Workbook

Sheet Accueil
B1: Cahier de recette
B2: Agri-Digit Bénin · plateforme multi-filières d'assistance et de conseil agricole (MAEP / MTDI)
B4: Informations de recette (cases jaunes à compléter)
B5: Version du cahier | C5: 1.0 · 28/10/2026
B6: Version logicielle testée | C6: ebf6047 (branche main) + modifications locales non commitées (menu par rubriques, cahier de recette)
B7: Environnement (URL) | C7: http://localhost:5173 (démonstration locale)
B8: Navigateur et version | C8: Chromium (Playwright) pour l'interface ; essais de l'API en Python
B9: Poste ou appareil | C9: PC Windows 10, essais automatisés (écran 1280 px, puis 390 px pour le mobile)
B10: Début de la recette | C10: 28/10/2026
B11: Fin de la recette | C11: À renseigner (JJ/MM/AAAA)
B12: Responsable de la recette | C12: À renseigner : nom et fonction
B14: Mode d'emploi
B15: Étape 1 | C15: Lancer l'application (start.bat) et ouvrir http://localhost:5173. Le code de connexion s'affiche dans le bandeau « Simulation » (comptes dans l'onglet « Comptes de test »).
B16: Étape 2 | C16: Dans « Cas de test », filtrer par catégorie, module ou rôle (filtres de la ligne d'en-tête) et dérouler les cas, les P1 d'abord.
B17: Étape 3 | C17: Pour chaque cas : appliquer les pré-conditions, suivre les étapes, comparer le résultat avec « Résultat attendu ».
B18: Étape 4 | C18: Noter ce qui a été observé dans « Résultat obtenu », choisir le Statut dans la liste, puis renseigner Testeur et Date (colonnes sur fond jaune).
B19: Étape 5 | C19: En cas d'écart (KO) : ajouter une ligne dans « Anomalies » (N° ANO-001…) et reporter ce N° dans la colonne « N° anomalie » du cas.
B20: Étape 6 | C20: L'onglet « Synthèse » se met à jour seul : avancement, taux de réussite, anomalies ouvertes et décision de recette.
B22: Légende des statuts
B23: À tester | C23: Pas encore exécuté (valeur par défaut).
B24: En cours | C24: Exécution commencée, non terminée.
B25: OK | C25: Résultat obtenu conforme au résultat attendu.
B26: KO | C26: Écart constaté : créer une ligne dans l'onglet Anomalies et reporter son N°.
B27: Bloqué | C27: Test impossible (pré-condition ou dépendance indisponible) : préciser dans Commentaires.
B28: Non applicable | C28: Hors périmètre de cette recette : justifier dans Commentaires.
B30: Priorités des cas et gravité des anomalies
B31: P1 · Critique | C31: Parcours indispensable : un KO empêche la validation de la recette.
B32: P2 · Important | C32: Fonction attendue : un KO est toléré avec un plan de correction daté.
B33: P3 · Confort | C33: Amélioration, cas limite ou écart déjà connu.
B34: Anomalie bloquante | C34: Empêche d'utiliser la fonction, ou expose / perd des données.
B35: Anomalie majeure | C35: Fonction dégradée, contournement pénible.
B36: Anomalie mineure | C36: Gêne limitée.
B37: Anomalie cosmétique | C37: Présentation, libellé, alignement.
B39: À savoir avant de tester
B40: • Les SMS, l'USSD, l'ANIP, le paiement FakePay et le diagnostic par photo sont simulés : c'est attendu. Le test vérifie que l'écran l'indique (« Simulation », « Démonstration »), pas un résultat réel.
B41: • Chrome est recommandé. Le relief 3D du suivi satellite demande WebGL ; sans clés Copernicus, le satellite reste en démonstration étiquetée.
B42: • Aucun texte en langue nationale (fon, bariba, yoruba, dendi) n'existe tant que le MTDI ne l'a pas écrit : l'assistant répond alors en français et le dit.
B43: • Les pages « Collecte » et « Offres » contiennent des données de démonstration écrites dans le code : écart connu, à tester en P3.
B44: • Les chiffres du tableau de bord sont des données de démonstration : vérifier leur étiquetage et leur source, pas leur exactitude.
B46: Exemple de saisie (ne pas recopier)
...

Sheet Synthèse
B1: Synthèse de la recette
B2: Mise à jour automatique depuis les onglets « Cas de test » et « Anomalies » : ne rien saisir ici.
B4: CAS DE TEST | C4: AVANCEMENT | F4: TAUX DE RÉUSSITE | H4: ANOMALIES OUVERTES | J4: DÉCISION
B5: =COUNTA('Cas de test'!$A$5:$A$300) -> 134 | C5: =IF(COUNTA('Cas de test'!$A$5:$A$300)-COUNTIF('Cas de test'!$K$5:$K$300,"Non applicable")=0,0,(COUNTIF('Cas de test'!$K$5:$K$300,"OK")+COUNTIF('Cas de test'!$K$5:$K$300,"KO"))/(COUNTA('Cas de test'!$A$5:$A$300)-COUNTIF('Cas de test'!$K$5:$K$300,"Non applicable"))) -> 0.91044776 | F5: =IF(COUNTIF('Cas de test'!$K$5:$K$300,"OK")+COUNTIF('Cas de test'!$K$5:$K$300,"KO")=0,0,COUNTIF('Cas de test'!$K$5:$K$300,"OK")/(COUNTIF('Cas de test'!$K$5:$K$300,"OK")+COUNTIF('Cas de test'!$K$5:$K$300,"KO"))) -> 1 | H5: =COUNTIF(Anomalies!$H$5:$H$104,"Ouverte")+COUNTIF(Anomalies!$H$5:$H$104,"En correction")+COUNTIF(Anomalies!$H$5:$H$104,"Corrigée")+COUNTIF(Anomalies!$H$5:$H$104,"À retester") -> 3 | J5: =IF(COUNTIFS('Cas de test'!$F$5:$F$300,"P1",'Cas de test'!$K$5:$K$300,"KO")+COUNTIFS('Cas de test'!$F$5:$F$300,"P1",'Cas de test'!$K$5:$K$300,"Bloqué")>0,"NON PRÊT : cas P1 en échec ou bloqués",IF(COUNTIF('Cas de test'!$K$5:$K$300,"À tester")+COUNTIF('Cas de test'!$K$5:$K$300,"En cours")>0,"EN COURS","PRÊT À VALIDER")) -> EN COURS
B7: Par catégorie (modules de la fiche synthétique)
B8: Catégorie | C8: Total | D8: À tester | E8: En cours | F8: OK | G8: KO | H8: Bloqué | I8: Non applicable | J8: Avancement | K8: Réussite
B9: Enregistrement | C9: =COUNTIFS('Cas de test'!$B$5:$B$300,$B9) -> 25 | D9: =COUNTIFS('Cas de test'!$B$5:$B$300,$B9,'Cas de test'!$K$5:$K$300,D$8) -> 0 | E9: =COUNTIFS('Cas de test'!$B$5:$B$300,$B9,'Cas de test'!$K$5:$K$300,E$8) -> 2 | F9: =COUNTIFS('Cas de test'!$B$5:$B$300,$B9,'Cas de test'!$K$5:$K$300,F$8) -> 23 | G9: =COUNTIFS('Cas de test'!$B$5:$B$300,$B9,'Cas de test'!$K$5:$K$300,G$8) -> 0 | H9: =COUNTIFS('Cas de test'!$B$5:$B$300,$B9,'Cas de test'!$K$5:$K$300,H$8) -> 0 | I9: =COUNTIFS('Cas de test'!$B$5:$B$300,$B9,'Cas de test'!$K$5:$K$300,I$8) -> 0 | J9: =IF(C9-I9=0,0,(F9+G9)/(C9-I9)) -> 0.92 | K9: =IF(F9+G9=0,0,F9/(F9+G9)) -> 1
B10: Suivi | C10: =COUNTIFS('Cas de test'!$B$5:$B$300,$B10) -> 27 | D10: =COUNTIFS('Cas de test'!$B$5:$B$300,$B10,'Cas de test'!$K$5:$K$300,D$8) -> 0 | E10: =COUNTIFS('Cas de test'!$B$5:$B$300,$B10,'Cas de test'!$K$5:$K$300,E$8) -> 0 | F10: =COUNTIFS('Cas de test'!$B$5:$B$300,$B10,'Cas de test'!$K$5:$K$300,F$8) -> 27 | G10: =COUNTIFS('Cas de test'!$B$5:$B$300,$B10,'Cas de test'!$K$5:$K$300,G$8) -> 0 | H10: =COUNTIFS('Cas de test'!$B$5:$B$300,$B10,'Cas de test'!$K$5:$K$300,H$8) -> 0 | I10: =COUNTIFS('Cas de test'!$B$5:$B$300,$B10,'Cas de test'!$K$5:$K$300,I$8) -> 0 | J10: =IF(C10-I10=0,0,(F10+G10)/(C10-I10)) -> 1 | K10: =IF(F10+G10=0,0,F10/(F10+G10)) -> 1
B11: Intelligence artificielle | C11: =COUNTIFS('Cas de test'!$B$5:$B$300,$B11) -> 25 | D11: =COUNTIFS('Cas de test'!$B$5:$B$300,$B11,'Cas de test'!$K$5:$K$300,D$8) -> 0 | E11: =COUNTIFS('Cas de test'!$B$5:$B$300,$B11,'Cas de test'!$K$5:$K$300,E$8) -> 6 | F11: =COUNTIFS('Cas de test'!$B$5:$B$300,$B11,'Cas de test'!$K$5:$K$300,F$8) -> 19 | G11: =COUNTIFS('Cas de test'!$B$5:$B$300,$B11,'Cas de test'!$K$5:$K$300,G$8) -> 0 | H11: =COUNTIFS('Cas de test'!$B$5:$B$300,$B11,'Cas de test'!$K$5:$K$300,H$8) -> 0 | I11: =COUNTIFS('Cas de test'!$B$5:$B$300,$B11,'Cas de test'!$K$5:$K$300,I$8) -> 0 | J11: =IF(C11-I11=0,0,(F11+G11)/(C11-I11)) -> 0.76 | K11: =IF(F11+G11=0,0,F11/(F11+G11)) -> 1
B12: Marketplace | C12: =COUNTIFS('Cas de test'!$B$5:$B$300,$B12) -> 15 | D12: =COUNTIFS('Cas de test'!$B$5:$B$300,$B12,'Cas de test'!$K$5:$K$300,D$8) -> 0 | E12: =COUNTIFS('Cas de test'!$B$5:$B$300,$B12,'Cas de test'!$K$5:$K$300,E$8) -> 1 | F12: =COUNTIFS('Cas de test'!$B$5:$B$300,$B12,'Cas de test'!$K$5:$K$300,F$8) -> 13 | G12: =COUNTIFS('Cas de test'!$B$5:$B$300,$B12,'Cas de test'!$K$5:$K$300,G$8) -> 0 | H12: =COUNTIFS('Cas de test'!$B$5:$B$300,$B12,'Cas de test'!$K$5:$K$300,H$8) -> 1 | I12: =COUNTIFS('Cas de test'!$B$5:$B$300,$B12,'Cas de test'!$K$5:$K$300,I$8) -> 0 | J12: =IF(C12-I12=0,0,(F12+G12)/(C12-I12)) -> 0.86666667 | K12: =IF(F12+G12=0,0,F12/(F12+G12)) -> 1
B13: Transverse | C13: =COUNTIFS('Cas de test'!$B$5:$B$300,$B13) -> 42 | D13: =COUNTIFS('Cas de test'!$B$5:$B$300,$B13,'Cas de test'!$K$5:$K$300,D$8) -> 2 | E13: =COUNTIFS('Cas de test'!$B$5:$B$300,$B13,'Cas de test'!$K$5:$K$300,E$8) -> 0 | F13: =COUNTIFS('Cas de test'!$B$5:$B$300,$B13,'Cas de test'!$K$5:$K$300,F$8) -> 40 | G13: =COUNTIFS('Cas de test'!$B$5:$B$300,$B13,'Cas de test'!$K$5:$K$300,G$8) -> 0 | H13: =COUNTIFS('Cas de test'!$B$5:$B$300,$B13,'Cas de test'!$K$5:$K$300,H$8) -> 0 | I13: =COUNTIFS('Cas de test'!$B$5:$B$300,$B13,'Cas de test'!$K$5:$K$300,I$8) -> 0 | J13: =IF(C13-I13=0,0,(F13+G13)/(C13-I13)) -> 0.95238095 | K13: =IF(F13+G13=0,0,F13/(F13+G13)) -> 1
B14: Total | C14: =SUM(C9:C13) -> 134 | D14: =SUM(D9:D13) -> 2 | E14: =SUM(E9:E13) -> 9 | F14: =SUM(F9:F13) -> 122 | G14: =SUM(G9:G13) -> 0 | H14: =SUM(H9:H13) -> 1 | I14: =SUM(I9:I13) -> 0 | J14: =IF(C14-I14=0,0,(F14+G14)/(C14-I14)) -> 0.91044776 | K14: =IF(F14+G14=0,0,F14/(F14+G14)) -> 1
B16: Par module
B17: Module | C17: Total | D17: À tester | E17: En cours | F17: OK | G17: KO | H17: Bloqué | I17: Non applicable | J17: Avancement | K17: Réussite
B18: Registre acteurs et actifs | C18: =COUNTIFS('Cas de test'!$C$5:$C$300,$B18) -> 16 | D18: =COUNTIFS('Cas de test'!$C$5:$C$300,$B18,'Cas de test'!$K$5:$K$300,D$17) -> 0 | E18: =COUNTIFS('Cas de test'!$C$5:$C$300,$B18,'Cas de test'!$K$5:$K$300,E$17) -> 0 | F18: =COUNTIFS('Cas de test'!$C$5:$C$300,$B18,'Cas de test'!$K$5:$K$300,F$17) -> 16 | G18: =COUNTIFS('Cas de test'!$C$5:$C$300,$B18,'Cas de test'!$K$5:$K$300,G$17) -> 0 | H18: =COUNTIFS('Cas de test'!$C$5:$C$300,$B18,'Cas de test'!$K$5:$K$300,H$17) -> 0 | I18: =COUNTIFS('Cas de test'!$C$5:$C$300,$B18,'Cas de test'!$K$5:$K$300,I$17) -> 0 | J18: =IF(C18-I18=0,0,(F18+G18)/(C18-I18)) -> 1 | K18: =IF(F18+G18=0,0,F18/(F18+G18)) -> 1
B19: Cartographie GPS parcellaire | C19: =COUNTIFS('Cas de test'!$C$5:$C$300,$B19) -> 9 | D19: =COUNTIFS('Cas de test'!$C$5:$C$300,$B19,'Cas de test'!$K$5:$K$300,D$17) -> 0 | E19: =COUNTIFS('Cas de test'!$C$5:$C$300,$B19,'Cas de test'!$K$5:$K$300,E$17) -> 2 | F19: =COUNTIFS('Cas de test'!$C$5:$C$300,$B19,'Cas de test'!$K$5:$K$300,F$17) -> 7 | G19: =COUNTIFS('Cas de test'!$C$5:$C$300,$B19,'Cas de test'!$K$5:$K$300,G$17) -> 0 | H19: =COUNTIFS('Cas de test'!$C$5:$C$300,$B19,'Cas de test'!$K$5:$K$300,H$17) -> 0 | I19: =COUNTIFS('Cas de test'!$C$5:$C$300,$B19,'Cas de test'!$K$5:$K$300,I$17) -> 0 | J19: =IF(C19-I19=0,0,(F19+G19)/(C19-I19)) -> 0.77777778 | K19: =IF(F19+G19=0,0,F19/(F19+G19)) -> 1
B20: Suivi production et filières | C20: =COUNTIFS('Cas de test'!$C$5:$C$300,$B20) -> 9 | D20: =COUNTIFS('Cas de test'!$C$5:$C$300,$B20,'Cas de test'!$K$5:$K$300,D$17) -> 0 | E20: =COUNTIFS('Cas de test'!$C$5:$C$300,$B20,'Cas de test'!$K$5:$K$300,E$17) -> 0 | F20: =COUNTIFS('Cas de test'!$C$5:$C$300,$B20,'Cas de test'!$K$5:$K$300,F$17) -> 9 | G20: =COUNTIFS('Cas de test'!$C$5:$C$300,$B20,'Cas de test'!$K$5:$K$300,G$17) -> 0 | H20: =COUNTIFS('Cas de test'!$C$5:$C$300,$B20,'Cas de test'!$K$5:$K$300,H$17) -> 0 | I20: =COUNTIFS('Cas de test'!$C$5:$C$300,$B20,'Cas de test'!$K$5:$K$300,I$17) -> 0 | J20: =IF(C20-I20=0,0,(F20+G20)/(C20-I20)) -> 1 | K20: =IF(F20+G20=0,0,F20/(F20+G20)) -> 1
B21: Gouvernance et appuis | C21: =COUNTIFS('Cas de test'!$C$5:$C$300,$B21) -> 12 | D21: =COUNTIFS('Cas de test'!$C$5:$C$300,$B21,'Cas de test'!$K$5:$K$300,D$17) -> 0 | E21: =COUNTIFS('Cas de test'!$C$5:$C$300,$B21,'Cas de test'!$K$5:$K$300,E$17) -> 0 | F21: =COUNTIFS('Cas de test'!$C$5:$C$300,$B21,'Cas de test'!$K$5:$K$300,F$17) -> 12 | G21: =COUNTIFS('Cas de test'!$C$5:$C$300,$B21,'Cas de test'!$K$5:$K$300,G$17) -> 0 | H21: =COUNTIFS('Cas de test'!$C$5:$C$300,$B21,'Cas de test'!$K$5:$K$300,H$17) -> 0 | I21: =COUNTIFS('Cas de test'!$C$5:$C$300,$B21,'Cas de test'!$K$5:$K$300,I$17) -> 0 | J21: =IF(C21-I21=0,0,(F21+G21)/(C21-I21)) -> 1 | K21: =IF(F21+G21=0,0,F21/(F21+G21)) -> 1
B22: Dashboard et suivi-évaluation | C22: =COUNTIFS('Cas de test'!$C$5:$C$300,$B22) -> 6 | D22: =COUNTIFS('Cas de test'!$C$5:$C$300,$B22,'Cas de test'!$K$5:$K$300,D$17) -> 0 | E22: =COUNTIFS('Cas de test'!$C$5:$C$300,$B22,'Cas de test'!$K$5:$K$300,E$17) -> 0 | F22: =COUNTIFS('Cas de test'!$C$5:$C$300,$B22,'Cas de test'!$K$5:$K$300,F$17) -> 6 | G22: =COUNTIFS('Cas de test'!$C$5:$C$300,$B22,'Cas de test'!$K$5:$K$300,G$17) -> 0 | H22: =COUNTIFS('Cas de test'!$C$5:$C$300,$B22,'Cas de test'!$K$5:$K$300,H$17) -> 0 | I22: =COUNTIFS('Cas de test'!$C$5:$C$300,$B22,'Cas de test'!$K$5:$K$300,I$17) -> 0 | J22: =IF(C22-I22=0,0,(F22+G22)/(C22-I22)) -> 1 | K22: =IF(F22+G22=0,0,F22/(F22+G22)) -> 1
B23: Assistant IA agronomique | C23: =COUNTIFS('Cas de test'!$C$5:$C$300,$B23) -> 6 | D23: =COUNTIFS('Cas de test'!$C$5:$C$300,$B23,'Cas de test'!$K$5:$K$300,D$17) -> 0 | E23: =COUNTIFS('Cas de test'!$C$5:$C$300,$B23,'Cas de test'!$K$5:$K$300,E$17) -> 2 | F23: =COUNTIFS('Cas de test'!$C$5:$C$300,$B23,'Cas de test'!$K$5:$K$300,F$17) -> 4 | G23: =COUNTIFS('Cas de test'!$C$5:$C$300,$B23,'Cas de test'!$K$5:$K$300,G$17) -> 0 | H23: =COUNTIFS('Cas de test'!$C$5:$C$300,$B23,'Cas de test'!$K$5:$K$300,H$17) -> 0 | I23: =COUNTIFS('Cas de test'!$C$5:$C$300,$B23,'Cas de test'!$K$5:$K$300,I$17) -> 0 | J23: =IF(C23-I23=0,0,(F23+G23)/(C23-I23)) -> 0.66666667 | K23: =IF(F23+G23=0,0,F23/(F23+G23)) -> 1
B24: Module linguistique (langues nationales) | C24: =COUNTIFS('Cas de test'!$C$5:$C$300,$B24) -> 6 | D24: =COUNTIFS('Cas de test'!$C$5:$C$300,$B24,'Cas de test'!$K$5:$K$300,D$17) -> 0 | E24: =COUNTIFS('Cas de test'!$C$5:$C$300,$B24,'Cas de test'!$K$5:$K$300,E$17) -> 2 | F24: =COUNTIFS('Cas de test'!$C$5:$C$300,$B24,'Cas de test'!$K$5:$K$300,F$17) -> 4 | G24: =COUNTIFS('Cas de test'!$C$5:$C$300,$B24,'Cas de test'!$K$5:$K$300,G$17) -> 0 | H24: =COUNTIFS('Cas de test'!$C$5:$C$300,$B24,'Cas de test'!$K$5:$K$300,H$17) -> 0 | I24: =COUNTIFS('Cas de test'!$C$5:$C$300,$B24,'Cas de test'!$K$5:$K$300,I$17) -> 0 | J24: =IF(C24-I24=0,0,(F24+G24)/(C24-I24)) -> 0.66666667 | K24: =IF(F24+G24=0,0,F24/(F24+G24)) -> 1
B25: Diagnostic phytosanitaire par image | C25: =COUNTIFS('Cas de test'!$C$5:$C$300,$B25) -> 6 | D25: =COUNTIFS('Cas de test'!$C$5:$C$300,$B25,'Cas de test'!$K$5:$K$300,D$17) -> 0 | E25: =COUNTIFS('Cas de test'!$C$5:$C$300,$B25,'Cas de test'!$K$5:$K$300,E$17) -> 1 | F25: =COUNTIFS('Cas de test'!$C$5:$C$300,$B25,'Cas de test'!$K$5:$K$300,F$17) -> 5 | G25: =COUNTIFS('Cas de test'!$C$5:$C$300,$B25,'Cas de test'!$K$5:$K$300,G$17) -> 0 | H25: =COUNTIFS('Cas de test'!$C$5:$C$300,$B25,'Cas de test'!$K$5:$K$300,H$17) -> 0 | I25: =COUNTIFS('Cas de test'!$C$5:$C$300,$B25,'Cas de test'!$K$5:$K$300,I$17) -> 0 | J25: =IF(C25-I25=0,0,(F25+G25)/(C25-I25)) -> 0.83333333 | K25: =IF(F25+G25=0,0,F25/(F25+G25)) -> 1
B26: Scoring crédit et aléas climatiques | C26: =COUNTIFS('Cas de test'!$C$5:$C$300,$B26) -> 7 | D26: =COUNTIFS('Cas de test'!$C$5:$C$300,$B26,'Cas de test'!$K$5:$K$300,D$17) -> 0 | E26: =COUNTIFS('Cas de test'!$C$5:$C$300,$B26,'Cas de test'!$K$5:$K$300,E$17) -> 1 | F26: =COUNTIFS('Cas de test'!$C$5:$C$300,$B26,'Cas de test'!$K$5:$K$300,F$17) -> 6 | G26: =COUNTIFS('Cas de test'!$C$5:$C$300,$B26,'Cas de test'!$K$5:$K$300,G$17) -> 0 | H26: =COUNTIFS('Cas de test'!$C$5:$C$300,$B26,'Cas de test'!$K$5:$K$300,H$17) -> 0 | I26: =COUNTIFS('Cas de test'!$C$5:$C$300,$B26,'Cas de test'!$K$5:$K$300,I$17) -> 0 | J26: =IF(C26-I26=0,0,(F26+G26)/(C26-I26)) -> 0.85714286 | K26: =IF(F26+G26=0,0,F26/(F26+G26)) -> 1
B27: Valorisation des produits | C27: =COUNTIFS('Cas de test'!$C$5:$C$300,$B27) -> 11 | D27: =COUNTIFS('Cas de test'!$C$5:$C$300,$B27,'Cas de test'!$K$5:$K$300,D$17) -> 0 | E27: =COUNTIFS('Cas de test'!$C$5:$C$300,$B27,'Cas de test'!$K$5:$K$300,E$17) -> 1 | F27: =COUNTIFS('Cas de test'!$C$5:$C$300,$B27,'Cas de test'!$K$5:$K$300,F$17) -> 9 | G27: =COUNTIFS('Cas de test'!$C$5:$C$300,$B27,'Cas de test'!$K$5:$K$300,G$17) -> 0 | H27: =COUNTIFS('Cas de test'!$C$5:$C$300,$B27,'Cas de test'!$K$5:$K$300,H$17) -> 1 | I27: =COUNTIFS('Cas de test'!$C$5:$C$300,$B27,'Cas de test'!$K$5:$K$300,I$17) -> 0 | J27: =IF(C27-I27=0,0,(F27+G27)/(C27-I27)) -> 0.81818182 | K27: =IF(F27+G27=0,0,F27/(F27+G27)) -> 1
B28: Services partenaires (fintech) | C28: =COUNTIFS('Cas de test'!$C$5:$C$300,$B28) -> 4 | D28: =COUNTIFS('Cas de test'!$C$5:$C$300,$B28,'Cas de test'!$K$5:$K$300,D$17) -> 0 | E28: =COUNTIFS('Cas de test'!$C$5:$C$300,$B28,'Cas de test'!$K$5:$K$300,E$17) -> 0 | F28: =COUNTIFS('Cas de test'!$C$5:$C$300,$B28,'Cas de test'!$K$5:$K$300,F$17) -> 4 | G28: =COUNTIFS('Cas de test'!$C$5:$C$300,$B28,'Cas de test'!$K$5:$K$300,G$17) -> 0 | H28: =COUNTIFS('Cas de test'!$C$5:$C$300,$B28,'Cas de test'!$K$5:$K$300,H$17) -> 0 | I28: =COUNTIFS('Cas de test'!$C$5:$C$300,$B28,'Cas de test'!$K$5:$K$300,I$17) -> 0 | J28: =IF(C28-I28=0,0,(F28+G28)/(C28-I28)) -> 1 | K28: =IF(F28+G28=0,0,F28/(F28+G28)) -> 1
B29: Connexion et comptes | C29: =COUNTIFS('Cas de test'!$C$5:$C$300,$B29) -> 9 | D29: =COUNTIFS('Cas de test'!$C$5:$C$300,$B29,'Cas de test'!$K$5:$K$300,D$17) -> 0 | E29: =COUNTIFS('Cas de test'!$C$5:$C$300,$B29,'Cas de test'!$K$5:$K$300,E$17) -> 0 | F29: =COUNTIFS('Cas de test'!$C$5:$C$300,$B29,'Cas de test'!$K$5:$K$300,F$17) -> 9 | G29: =COUNTIFS('Cas de test'!$C$5:$C$300,$B29,'Cas de test'!$K$5:$K$300,G$17) -> 0 | H29: =COUNTIFS('Cas de test'!$C$5:$C$300,$B29,'Cas de test'!$K$5:$K$300,H$17) -> 0 | I29: =COUNTIFS('Cas de test'!$C$5:$C$300,$B29,'Cas de test'!$K$5:$K$300,I$17) -> 0 | J29: =IF(C29-I29=0,0,(F29+G29)/(C29-I29)) -> 1 | K29: =IF(F29+G29=0,0,F29/(F29+G29)) -> 1
... B32: Hors ligne, mobile et téléphone simple | C32: =COUNTIFS('Cas de test'!$C$5:$C$300,$B32) -> 6 | D32: =COUNTIFS('Cas de test'!$C$5:$C$300,$B32,'Cas de test'!$K$5:$K$300,D$17) -> 2 | E32: =COUNTIFS('Cas de test'!$C$5:$C$300,$B32,'Cas de test'!$K$5:$K$300,E$17) -> 0 | F32: =COUNTIFS('Cas de test'!$C$5:$C$300,$B32,'Cas de test'!$K$5:$K$300,F$17) -> 4 | G32: =COUNTIFS('Cas de test'!$C$5:$C$300,$B32,'Cas de test'!$K$5:$K$300,G$17) -> 0 | H32: =COUNTIFS('Cas de test'!$C$5:$C$300,$B32,'Cas de test'!$K$5:$K$300,H$17) -> 0 | I32: =COUNTIFS('Cas de test'!$C$5:$C$300,$B32,'Cas de test'!$K$5:$K$300,I$17) -> 0 | J32: =IF(C32-I32=0,0,(F32+G32)/(C32-I32)) -> 0.66666667 | K32: =IF(F32+G32=0,0,F32/(F32+G32)) -> 1
B33: Total | C33: =SUM(C18:C32) -> 134 | D33: =SUM(D18:D32) -> 2 | E33: =SUM(E18:E32) -> 9 | F33: =SUM(F18:F32) -> 122 | G33: =SUM(G18:G32) -> 0 | H33: =SUM(H18:H32) -> 1 | I33: =SUM(I18:I32) -> 0 | J33: =IF(C33-I33=0,0,(F33+G33)/(C33-I33)) -> 0.91044776 | K33: =IF(F33+G33=0,0,F33/(F33+G33)) -> 1
B35: Par rôle (un cas multi-rôle compte pour chacun de ses rôles)
B36: Rôle | C36: Total | D36: À tester | E36: En cours | F36: OK | G36: KO | H36: Bloqué | I36: Non applicable | J36: Avancement | K36: Réussite
B37: Producteur | C37: =COUNTIFS('Cas de test'!$E$5:$E$300,"*"&$B37&"*") -> 52 | D37: =COUNTIFS('Cas de test'!$E$5:$E$300,"*"&$B37&"*",'Cas de test'!$K$5:$K$300,D$36) -> 2 | E37: =COUNTIFS('Cas de test'!$E$5:$E$300,"*"&$B37&"*",'Cas de test'!$K$5:$K$300,E$36) -> 5 | F37: =COUNTIFS('Cas de test'!$E$5:$E$300,"*"&$B37&"*",'Cas de test'!$K$5:$K$300,F$36) -> 44 | G37: =COUNTIFS('Cas de test'!$E$5:$E$300,"*"&$B37&"*",'Cas de test'!$K$5:$K$300,G$36) -> 0 | H37: =COUNTIFS('Cas de test'!$E$5:$E$300,"*"&$B37&"*",'Cas de test'!$K$5:$K$300,H$36) -> 1 | I37: =COUNTIFS('Cas de test'!$E$5:$E$300,"*"&$B37&"*",'Cas de test'!$K$5:$K$300,I$36) -> 0 | J37: =IF(C37-I37=0,0,(F37+G37)/(C37-I37)) -> 0.84615385 | K37: =IF(F37+G37=0,0,F37/(F37+G37)) -> 1
B38: Agent ATDA | C38: =COUNTIFS('Cas de test'!$E$5:$E$300,"*"&$B38&"*") -> 36 | D38: =COUNTIFS('Cas de test'!$E$5:$E$300,"*"&$B38&"*",'Cas de test'!$K$5:$K$300,D$36) -> 1 | E38: =COUNTIFS('Cas de test'!$E$5:$E$300,"*"&$B38&"*",'Cas de test'!$K$5:$K$300,E$36) -> 0 | F38: =COUNTIFS('Cas de test'!$E$5:$E$300,"*"&$B38&"*",'Cas de test'!$K$5:$K$300,F$36) -> 35 | G38: =COUNTIFS('Cas de test'!$E$5:$E$300,"*"&$B38&"*",'Cas de test'!$K$5:$K$300,G$36) -> 0 | H38: =COUNTIFS('Cas de test'!$E$5:$E$300,"*"&$B38&"*",'Cas de test'!$K$5:$K$300,H$36) -> 0 | I38: =COUNTIFS('Cas de test'!$E$5:$E$300,"*"&$B38&"*",'Cas de test'!$K$5:$K$300,I$36) -> 0 | J38: =IF(C38-I38=0,0,(F38+G38)/(C38-I38)) -> 0.97222222 | K38: =IF(F38+G38=0,0,F38/(F38+G38)) -> 1
B39: Agronome INRAB | C39: =COUNTIFS('Cas de test'!$E$5:$E$300,"*"&$B39&"*") -> 6 | D39: =COUNTIFS('Cas de test'!$E$5:$E$300,"*"&$B39&"*",'Cas de test'!$K$5:$K$300,D$36) -> 0 | E39: =COUNTIFS('Cas de test'!$E$5:$E$300,"*"&$B39&"*",'Cas de test'!$K$5:$K$300,E$36) -> 0 | F39: =COUNTIFS('Cas de test'!$E$5:$E$300,"*"&$B39&"*",'Cas de test'!$K$5:$K$300,F$36) -> 6 | G39: =COUNTIFS('Cas de test'!$E$5:$E$300,"*"&$B39&"*",'Cas de test'!$K$5:$K$300,G$36) -> 0 | H39: =COUNTIFS('Cas de test'!$E$5:$E$300,"*"&$B39&"*",'Cas de test'!$K$5:$K$300,H$36) -> 0 | I39: =COUNTIFS('Cas de test'!$E$5:$E$300,"*"&$B39&"*",'Cas de test'!$K$5:$K$300,I$36) -> 0 | J39: =IF(C39-I39=0,0,(F39+G39)/(C39-I39)) -> 1 | K39: =IF(F39+G39=0,0,F39/(F39+G39)) -> 1
B40: Responsable de programme | C40: =COUNTIFS('Cas de test'!$E$5:$E$300,"*"&$B40&"*") -> 6 | D40: =COUNTIFS('Cas de test'!$E$5:$E$300,"*"&$B40&"*",'Cas de test'!$K$5:$K$300,D$36) -> 0 | E40: =COUNTIFS('Cas de test'!$E$5:$E$300,"*"&$B40&"*",'Cas de test'!$K$5:$K$300,E$36) -> 0 | F40: =COUNTIFS('Cas de test'!$E$5:$E$300,"*"&$B40&"*",'Cas de test'!$K$5:$K$300,F$36) -> 6 | G40: =COUNTIFS('Cas de test'!$E$5:$E$300,"*"&$B40&"*",'Cas de test'!$K$5:$K$300,G$36) -> 0 | H40: =COUNTIFS('Cas de test'!$E$5:$E$300,"*"&$B40&"*",'Cas de test'!$K$5:$K$300,H$36) -> 0 | I40: =COUNTIFS('Cas de test'!$E$5:$E$300,"*"&$B40&"*",'Cas de test'!$K$5:$K$300,I$36) -> 0 | J40: =IF(C40-I40=0,0,(F40+G40)/(C40-I40)) -> 1 | K40: =IF(F40+G40=0,0,F40/(F40+G40)) -> 1
B41: Administrateur MAEP | C41: =COUNTIFS('Cas de test'!$E$5:$E$300,"*"&$B41&"*") -> 18 | D41: =COUNTIFS('Cas de test'!$E$5:$E$300,"*"&$B41&"*",'Cas de test'!$K$5:$K$300,D$36) -> 0 | E41: =COUNTIFS('Cas de test'!$E$5:$E$300,"*"&$B41&"*",'Cas de test'!$K$5:$K$300,E$36) -> 0 | F41: =COUNTIFS('Cas de test'!$E$5:$E$300,"*"&$B41&"*",'Cas de test'!$K$5:$K$300,F$36) -> 18 | G41: =COUNTIFS('Cas de test'!$E$5:$E$300,"*"&$B41&"*",'Cas de test'!$K$5:$K$300,G$36) -> 0 | H41: =COUNTIFS('Cas de test'!$E$5:$E$300,"*"&$B41&"*",'Cas de test'!$K$5:$K$300,H$36) -> 0 | I41: =COUNTIFS('Cas de test'!$E$5:$E$300,"*"&$B41&"*",'Cas de test'!$K$5:$K$300,I$36) -> 0 | J41: =IF(C41-I41=0,0,(F41+G41)/(C41-I41)) -> 1 | K41: =IF(F41+G41=0,0,F41/(F41+G41)) -> 1
B42: Auditeur CoPil | C42: =COUNTIFS('Cas de test'!$E$5:$E$300,"*"&$B42&"*") -> 2 | D42: =COUNTIFS('Cas de test'!$E$5:$E$300,"*"&$B42&"*",'Cas de test'!$K$5:$K$300,D$36) -> 0 | E42: =COUNTIFS('Cas de test'!$E$5:$E$300,"*"&$B42&"*",'Cas de test'!$K$5:$K$300,E$36) -> 0 | F42: =COUNTIFS('Cas de test'!$E$5:$E$300,"*"&$B42&"*",'Cas de test'!$K$5:$K$300,F$36) -> 2 | G42: =COUNTIFS('Cas de test'!$E$5:$E$300,"*"&$B42&"*",'Cas de test'!$K$5:$K$300,G$36) -> 0 | H42: =COUNTIFS('Cas de test'!$E$5:$E$300,"*"&$B42&"*",'Cas de test'!$K$5:$K$300,H$36) -> 0 | I42: =COUNTIFS('Cas de test'!$E$5:$E$300,"*"&$B42&"*",'Cas de test'!$K$5:$K$300,I$36) -> 0 | J42: =IF(C42-I42=0,0,(F42+G42)/(C42-I42)) -> 1 | K42: =IF(F42+G42=0,0,F42/(F42+G42)) -> 1
B43: Agent financier | C43: =COUNTIFS('Cas de test'!$E$5:$E$300,"*"&$B43&"*") -> 4 | D43: =COUNTIFS('Cas de test'!$E$5:$E$300,"*"&$B43&"*",'Cas de test'!$K$5:$K$300,D$36) -> 0 | E43: =COUNTIFS('Cas de test'!$E$5:$E$300,"*"&$B43&"*",'Cas de test'!$K$5:$K$300,E$36) -> 1 | F43: =COUNTIFS('Cas de test'!$E$5:$E$300,"*"&$B43&"*",'Cas de test'!$K$5:$K$300,F$36) -> 3 | G43: =COUNTIFS('Cas de test'!$E$5:$E$300,"*"&$B43&"*",'Cas de test'!$K$5:$K$300,G$36) -> 0 | H43: =COUNTIFS('Cas de test'!$E$5:$E$300,"*"&$B43&"*",'Cas de test'!$K$5:$K$300,H$36) -> 0 | I43: =COUNTIFS('Cas de test'!$E$5:$E$300,"*"&$B43&"*",'Cas de test'!$K$5:$K$300,I$36) -> 0 | J43: =IF(C43-I43=0,0,(F43+G43)/(C43-I43)) -> 0.75 | K43: =IF(F43+G43=0,0,F43/(F43+G43)) -> 1
B44: Gestionnaire de coopérative | C44: =COUNTIFS('Cas de test'!$E$5:$E$300,"*"&$B44&"*") -> 5 | D44: =COUNTIFS('Cas de test'!$E$5:$E$300,"*"&$B44&"*",'Cas de test'!$K$5:$K$300,D$36) -> 0 | E44: =COUNTIFS('Cas de test'!$E$5:$E$300,"*"&$B44&"*",'Cas de test'!$K$5:$K$300,E$36) -> 0 | F44: =COUNTIFS('Cas de test'!$E$5:$E$300,"*"&$B44&"*",'Cas de test'!$K$5:$K$300,F$36) -> 5 | G44: =COUNTIFS('Cas de test'!$E$5:$E$300,"*"&$B44&"*",'Cas de test'!$K$5:$K$300,G$36) -> 0 | H44: =COUNTIFS('Cas de test'!$E$5:$E$300,"*"&$B44&"*",'Cas de test'!$K$5:$K$300,H$36) -> 0 | I44: =COUNTIFS('Cas de test'!$E$5:$E$300,"*"&$B44&"*",'Cas de test'!$K$5:$K$300,I$36) -> 0 | J44: =IF(C44-I44=0,0,(F44+G44)/(C44-I44)) -> 1 | K44: =IF(F44+G44=0,0,F44/(F44+G44)) -> 1
B45: Transformateur | C45: =COUNTIFS('Cas de test'!$E$5:$E$300,"*"&$B45&"*") -> 13 | D45: =COUNTIFS('Cas de test'!$E$5:$E$300,"*"&$B45&"*",'Cas de test'!$K$5:$K$300,D$36) -> 0 | E45: =COUNTIFS('Cas de test'!$E$5:$E$300,"*"&$B45&"*",'Cas de test'!$K$5:$K$300,E$36) -> 0 | F45: =COUNTIFS('Cas de test'!$E$5:$E$300,"*"&$B45&"*",'Cas de test'!$K$5:$K$300,F$36) -> 13 | G45: =COUNTIFS('Cas de test'!$E$5:$E$300,"*"&$B45&"*",'Cas de test'!$K$5:$K$300,G$36) -> 0 | H45: =COUNTIFS('Cas de test'!$E$5:$E$300,"*"&$B45&"*",'Cas de test'!$K$5:$K$300,H$36) -> 0 | I45: =COUNTIFS('Cas de test'!$E$5:$E$300,"*"&$B45&"*",'Cas de test'!$K$5:$K$300,I$36) -> 0 | J45: =IF(C45-I45=0,0,(F45+G45)/(C45-I45)) -> 1 | K45: =IF(F45+G45=0,0,F45/(F45+G45)) -> 1
B46: Distributeur | C46: =COUNTIFS('Cas de test'!$E$5:$E$300,"*"&$B46&"*") -> 7 | D46: =COUNTIFS('Cas de test'!$E$5:$E$300,"*"&$B46&"*",'Cas de test'!$K$5:$K$300,D$36) -> 0 | E46: =COUNTIFS('Cas de test'!$E$5:$E$300,"*"&$B46&"*",'Cas de test'!$K$5:$K$300,E$36) -> 1 | F46: =COUNTIFS('Cas de test'!$E$5:$E$300,"*"&$B46&"*",'Cas de test'!$K$5:$K$300,F$36) -> 6 | G46: =COUNTIFS('Cas de test'!$E$5:$E$300,"*"&$B46&"*",'Cas de test'!$K$5:$K$300,G$36) -> 0 | H46: =COUNTIFS('Cas de test'!$E$5:$E$300,"*"&$B46&"*",'Cas de test'!$K$5:$K$300,H$36) -> 0 | I46: =COUNTIFS('Cas de test'!$E$5:$E$300,"*"&$B46&"*",'Cas de test'!$K$5:$K$300,I$36) -> 0 | J46: =IF(C46-I46=0,0,(F46+G46)/(C46-I46)) -> 0.85714286 | K46: =IF(F46+G46=0,0,F46/(F46+G46)) -> 1
...

Sheet Cas de test
A1: Cahier de recette · Cas de test
A2: ="Cas : "&COUNTA(A5:A300)&" · OK : "&COUNTIF(K5:K300,"OK")&" · KO : "&COUNTIF(K5:K300,"KO")&" · Bloqués : "&COUNTIF(K5:K300,"Bloqué")&" · À tester : "&COUNTIF(K5:K300,"À tester") -> Cas : 134 · OK : 122 · KO : 0 · Bloqués : 1 · À tester : 2
A3: CAS DE TEST · à ne pas modifier | J3: RÉSULTATS · à renseigner par le testeur
A4: N° | B4: Catégorie | C4: Module | D4: Page / route | E4: Rôle | F4: Priorité | G4: Pré-conditions | H4: Étapes | I4: Résultat attendu | J4: Résultat obtenu | K4: Statut | L4: Testeur | M4: Date | N4: N° anomalie | O4: Commentaires
A5: REG-01 | B5: Enregistrement | C5: Registre acteurs et actifs | D5: /inscription | E5: Public (non connecté) | F5: P1 | G5: Être déconnecté. Téléphone 0197000099 libre. | H5: 1. Ouvrir « S'inscrire ». 2. NPI 1000000002, Awa SABI, sexe F, né(e) le 1990-07-01, Alibori, Banikoara, téléphone 0197000099, langue français. 3. Cocher le consentement (présenté à part) puis valider. | I5: Fiche créée au statut « en attente » (code de la forme BJ-AGR-2026-0000xx). L'aide sous le NPI et le récapitulatif rappellent que l'ANIP est simulée. | K5: OK
A6: REG-02 | B6: Enregistrement | C6: Registre acteurs et actifs | D6: /inscription | E6: Public (non connecté) | F6: P2 | G6: Être déconnecté. | H6: 1. Ouvrir « S'inscrire ». 2. Saisir le NPI 1000000004. | I6: La demande de consentement parental s'affiche. | J6: Formulaire d'inscription avec une personne née en 2011 : à l'étape 4 « Consentement » apparaît « Moins de 16 ans : parent ou tuteur légal — Le consentement d'un titulaire de l'autorité parentale est obligatoire (loi n° 2017-20, art. 446) » avec les champs nom et NPI du parent ou tuteur ; le serveur refuse sans eux (400 guardian_required). | K6: OK | L6: Claude (essai automatisé) | M6: 46323 | O6: La demande apparaît à l'étape Consentement d'après la date de naissance, pas dès la saisie du NPI comme le dit le cahier.
A7: REG-03 | B7: Enregistrement | C7: Registre acteurs et actifs | D7: /inscription | E7: Public (non connecté) | F7: P2 | G7: Être déconnecté. | H7: 1. Remplir le formulaire d'inscription sans cocher le consentement. 2. Tenter de valider. | I7: L'inscription est impossible tant que le consentement n'est pas donné (bouton inactif ou message). | K7: OK
A8: REG-04 | B8: Enregistrement | C8: Registre acteurs et actifs | D8: /producteurs | E8: Agent ATDA | F8: P1 | G8: Connecté (téléphone 0197000002). Inscription d'Awa SABI faite (REG-01). | H8: 1. Ouvrir « Producteurs » : liste des producteurs en attente de l'Alibori. 2. Ouvrir la fiche d'Awa SABI. 3. Cliquer « Valider ». | I8: La fiche passe à « validée ». Le producteur reçoit une notification ; le SMS simulé apparaît dans « Boîte d'envoi ». | K8: OK
A9: REG-05 | B9: Enregistrement | C9: Registre acteurs et actifs | D9: /producteurs | E9: Agent ATDA | F9: P1 | G9: Connecté (téléphone 0197000002). | H9: 1. Parcourir la liste des producteurs. 2. Ouvrir une fiche (/producteurs/:id). | I9: Seuls les producteurs du département de l'agent (Alibori) sont visibles. La fiche s'ouvre sans erreur. | K9: OK
A10: REG-06 | B10: Enregistrement | C10: Registre acteurs et actifs | D10: /ma-carte | E10: Producteur | F10: P1 | G10: Connecté (téléphone 0197000001). | H10: 1. Ouvrir « Ma carte ». | I10: La carte affiche un code de vérification de 8 caractères et l'adresse de vérification. | K10: OK
A11: REG-07 | B11: Enregistrement | C11: Registre acteurs et actifs | D11: /verification/:code | E11: Public (non connecté) | F11: P1 | G11: Code lu sur « Ma carte ». Être déconnecté. | H11: 1. Ouvrir /verification/<code>. | I11: Seuls le statut et le nom apparaissent, aucune autre donnée personnelle. | K11: OK
A12: REG-08 | B12: Enregistrement | C12: Registre acteurs et actifs | D12: /ma-carte | E12: Producteur | F12: P2 | G12: Producteur dont la fiche n'est pas validée. | H12: 1. Ouvrir « Ma carte ». | I12: Une fiche non validée n'a pas de carte. | K12: OK
A13: REG-09 | B13: Enregistrement | C13: Registre acteurs et actifs | D13: /ma-carte | E13: Producteur | F13: P3 | G13: Connecté (téléphone 0197000001). | H13: 1. Ouvrir « Ma carte », cliquer « Partager le lien ». | I13: La feuille de partage du téléphone s'ouvre, ou le lien est copié. | K13: OK
A14: REG-10 | B14: Enregistrement | C14: Registre acteurs et actifs | D14: /cooperatives | E14: Gestionnaire de coopérative | F14: P1 | G14: Connecté (téléphone 0197000008). Producteur validé de l'Alibori non encore membre (ex. Awa SABI). | H14: 1. Ouvrir sa coopérative. 2. Ajouter le producteur par son code. 3. Mettre fin à l'adhésion avec un motif. 4. Ouvrir la vue « Historique (adhésions terminées) ». | I14: Le membre est ajouté puis son adhésion terminée ; l'historique reste visible. Le producteur retrouve ses adhésions dans « Mes coopératives ». | K14: OK
A15: REG-11 | B15: Enregistrement | C15: Registre acteurs et actifs | D15: /mes-cooperatives | E15: Producteur + Gestionnaire de coopérative | F15: P2 | G15: Producteur sans adhésion à la coopérative visée. | H15: 1. Producteur : « Mes coopératives », « Demander à adhérer » (message facultatif, accord sur ce que la coopérative voit). 2. Gestionnaire (0197000008) : sa coopérative, onglet « Demandes d'adhésion », accepter ou refuser avec un motif. | I15: L'acceptation crée l'adhésion ; le refus exige un motif. Le producteur est prévenu dans les deux cas. | J15: Demande d'adhésion déposée (201) et vue par le gestionnaire ; refus sans motif refusé (400 reason_required) ; refus avec motif accepté ; nouvelle demande acceptée : adhésion créée (1). Titres des notifications du producteur : Adhésion, Adhésion, Remboursement reçu, Remboursement reçu. | K15: OK | L15: Claude (essai automatisé) | M15: 46323 | O15: Vérifié par l'API.
A16: REG-12 | B16: Enregistrement | C16: Registre acteurs et actifs | D16: /mes-cooperatives | E16: Producteur | F16: P2 | G16: Connecté (téléphone 0197000001). (Bio GOUNOU, président). | H16: 1. Ouvrir « Mes coopératives » puis « Gérer la coopérative ». | I16: Le président voit membres et demandes d'adhésion comme le gestionnaire, sans pouvoir décider de sa propre demande. | J16: Le président (Bio GOUNOU) accède à sa coopérative (200), à ses membres (200) et aux demandes d'adhésion (200). | K16: OK | L16: Claude (essai automatisé) | M16: 46323 | O16: Vérifié par l'API ; l'impossibilité de décider de sa propre demande n'a pas été rejouée.
A17: REG-13 | B17: Enregistrement | C17: Registre acteurs et actifs | D17: /organisations | E17: Agent ATDA | F17: P2 | G17: Connecté (téléphone 0197000002). | H17: 1. Ouvrir « Organisations de filière ». 2. Ouvrir « Union communale des producteurs de maïs de Banikoara [démo] ». 3. Ajouter une réunion. | I17: Coopératives membres, effectifs, prix convenu et formation sont affichés ; la réunion ajoutée apparaît dans la liste. | J17: Organisation « Union communale des producteurs de maïs de Banikoara [démo] » : effectifs {'cooperatives': 1, 'producers': 6, 'women': 1} ; réunion ajoutée (201), visible dans la liste. | K17: OK | L17: Claude (essai automatisé) | M17: 46323 | O17: Vérifié par l'API.
A18: REG-14 | B18: Enregistrement | C18: Registre acteurs et actifs | D18: /materiels | E18: Producteur | F18: P2 | G18: Connecté (téléphone 0197000001). | H18: 1. Ouvrir « Mon matériel », déclarer un tracteur. 2. Cliquer « Proposer à la location » et saisir un tarif par hectare. | I18: Le matériel est enregistré (type, nombre, état) et proposé à la location au tarif saisi. | J18: Tracteur enregistré (201) et proposé à la location à 25 000 FCFA/ha ; la location sans tarif est refusée (400). | K18: OK | L18: Claude (essai automatisé) | M18: 46323 | O18: Vérifié par l'API.
A19: REG-15 | B19: Enregistrement | C19: Registre acteurs et actifs | D19: /materiels | E19: Agent ATDA | F19: P2 | G19: Connecté (téléphone 0197000002). Matériel déclaré (REG-14). | H19: 1. Ouvrir « Matériel agricole ». 2. Filtrer par type. | I19: Le matériel est vu par département et type avec le seul code producteur : aucun nom ni téléphone. | J19: L'agent voit 2 matériels de type tracteur dans son département, avec type, état, tarif, commune et le seul code producteur (BJ-AGR-…) : aucun nom ni téléphone. | K19: OK | L19: Claude (essai automatisé) | M19: 46323 | O19: Vérifié par l'API.
A20: REG-16 | B20: Enregistrement | C20: Registre acteurs et actifs | D20: /pmea | E20: Transformateur + Agent ATDA | F20: P2 | G20: Connecté (téléphone 0197000009). | H20: 1. Transformateur : « Entreprises agricoles », « Inscrire une entreprise ». 2. Producteur : vérifier que l'entreprise n'est pas encore listée. 3. Agent de la zone ou administrateur : « Vérifier » l'entreprise. | I20: Avant vérification seul son auteur la voit ; après vérification elle apparaît dans l'annuaire des producteurs du département. | J20: Entreprise inscrite par le transformateur (non vérifiée, visible de son auteur) ; absente de la liste d'un producteur ; vérifiée par l'administrateur (200, verified=True) ; un agent hors département est refusé (403). | K20: OK | L20: Claude (essai automatisé) | M20: 46323 | O20: Vérifié par l'API ; l'apparition dans l'annuaire d'un producteur du Borgou n'a pas été vue (aucun producteur de ce département).
A21: GPS-01 | B21: Enregistrement | C21: Cartographie GPS parcellaire | D21: /parcelles | E21: Producteur | F21: P1 | G21: Connecté (téléphone 0197000001). | H21: 1. Ouvrir « Mes parcelles ». 2. Dessiner un polygone sur la carte. 3. Enregistrer la parcelle. | I21: La surface s'affiche à l'écran puis est recalculée par le serveur à l'enregistrement ; la parcelle apparaît dans la liste. | J21: Polygone enregistré (201) ; surface recalculée par le serveur : 0.9772 ha pour un carré d'environ 100 m ; la parcelle figure dans la liste. | K21: OK | L21: Claude (essai automatisé) | M21: 46323 | O21: Vérifié par l'API : tracé à la souris sur la carte non joué.
A22: GPS-02 | B22: Enregistrement | C22: Cartographie GPS parcellaire | D22: /parcelles | E22: Producteur | F22: P2 | G22: Connecté (téléphone 0197000001). | H22: 1. Sur la carte de tracé, utiliser la recherche de lieu (ex. Banikoara). 2. Cliquer « Ma position » (accepter la géolocalisation). 3. Utiliser le tracé en un clic. | I22: La carte se recentre sur le lieu ou la position ; le tracé en un clic produit un polygone modifiable. | J22: Recherche de lieu « Banikoara » : une seule requête vers OpenStreetMap (Nominatim, pays Bénin) au clic sur « Chercher » ; « Ma position » (position simulée) affiche « Vous êtes ici, à environ 0 m près. Tracez maintenant le contour de votre champ. » ; le bouton « Tracer le contour de ma parcelle » est présent. | K22: En cours | L22: Claude (essai automatisé) | M22: 46323 | O22: Recentrage de la carte et polygone du tracé en un clic non vérifiés à l'œil.
A23: GPS-03 | B23: Enregistrement | C23: Cartographie GPS parcellaire | D23: /parcelles | E23: Producteur | F23: P2 | G23: Connecté (téléphone 0197000001). Une parcelle existante dans le département. | H23: 1. Tracer une nouvelle parcelle qui recouvre plus de 20 % d'une parcelle d'un autre producteur du même département. 2. Enregistrer. | I23: Une alerte de chevauchement s'affiche (c'est un avertissement, pas un blocage). | J23: Parcelle presque superposée à une parcelle d'un autre producteur : enregistrée (201) avec overlap_warning=True (avertissement, pas de blocage). | K23: OK | L23: Claude (essai automatisé) | M23: 46323 | O23: Vérifié par l'API ; texte de l'alerte non vu à l'écran.
A24: GPS-04 | B24: Enregistrement | C24: Cartographie GPS parcellaire | D24: /amenagements | E24: Agent ATDA | F24: P2 | G24: Connecté (téléphone 0197000002). | H24: 1. « Enregistrer un aménagement » : bas-fond de 120 ha dont 90 exploitables. 2. « Ajouter des travaux » (réhabilitation). 3. « Démarrer » puis « Terminer » les travaux. | I24: L'état suit les travaux : « À réhabiliter », puis « En travaux », puis « Opérationnel ». Les trois superficies sont cohérentes. | J24: Bas-fond 120 ha dont 90 exploitables (40 exploitées) enregistré ; état « a_rehabiliter » après ajout des travaux, « en_travaux » une fois démarrés, « operationnel » une fois terminés ; clôture avant démarrage refusée (400). | K24: OK | L24: Claude (essai automatisé) | M24: 46323 | O24: Vérifié par l'API.
A25: GPS-05 | B25: Enregistrement | C25: Cartographie GPS parcellaire | D25: /sols | E25: Producteur | F25: P2 | G25: Connecté (téléphone 0197000001). | H25: 1. Ouvrir « Sols et terres », « Mes terres ». 2. Déclarer la superficie exploitable d'une parcelle. | I25: La superficie exploitable est enregistrée ; la valeur par défaut reste la surface totale tant que rien n'est déclaré. | J25: Superficie exploitable 0,5 ha acceptée ; 99 ha (plus que la surface mesurée) refusée (400). | K25: OK | L25: Claude (essai automatisé) | M25: 46323 | O25: Vérifié par l'API.
A26: GPS-06 | B26: Enregistrement | C26: Cartographie GPS parcellaire | D26: /sols | E26: Agent ATDA + Producteur | F26: P2 | G26: Connecté (téléphone 0197000002). | H26: 1. Agent : « Analyses de sol », saisir pH 4,8, matière organique 1,4 %, phosphore 6 ppm pour un producteur. 2. Producteur : ouvrir « Sols et terres ». | I26: Le producteur lit « À corriger » et des conseils qualitatifs, sans aucune dose. | J26: Analyse (pH 4,8, MO 1,4 %, P 6 ppm) saisie par l'agent ; le producteur lit 4 constats qualitatifs (sol très acide, matière organique faible, phosphore faible, sol sableux) avec des conseils sans dose (« aucune dose n'est donnée ici ») ; la saisie par le producteur est refusée (403). | K26: OK | L26: Claude (essai automatisé) | M26: 46323 | O26: Vérifié par l'API ; le libellé « À corriger » de l'écran n'a pas été vu (le serveur renvoie les niveaux alerte/attention).
... A42: GOU-04 | B42: Suivi | C42: Gouvernance et appuis | D42: /recouvrement | E42: Agent ATDA + Administrateur MAEP | F42: P2 | G42: Appuis remboursables en cours. | H42: 1. Ouvrir « Recouvrement ». | I42: Reste dû, retards et taux de recouvrement par département sont affichés ; l'équipement du plateau d'un transformateur y figure. | J42: Recouvrement (agent, portefeuille) : 2 créances, 60 000 FCFA dont 40 000 payés, reste dû 20 000, retards 0 ; ventilation par type et par département (Alibori). | K42: OK | L42: Claude (essai automatisé) | M42: 46323 | O42: Vérifié par l'API ; taux de recouvrement null faute d'échéance échue ; équipement du plateau d'un transformateur non vérifié.
A43: GOU-05 | B43: Suivi | C43: Gouvernance et appuis | D43: /selection | E43: Responsable de programme | F43: P1 | G43: Connecté (téléphone 0197000004). | H43: 1. « Nouvelle sélection » : 2 000 bénéficiaires, poids par défaut (confiance 0,5, route 0,3, superficie 0,2), département Alibori. 2. Lancer. | I43: Une proposition est calculée (10 053 fermes évaluées sur la base de démonstration). | J43: Sélection de 2 000 bénéficiaires (poids 0,5 / 0,3 / 0,2, Alibori) lancée : statut « proposition », 2 000 retenus sur 38 468 fermes évaluées. | K43: OK | L43: Claude (essai automatisé) | M43: 46323 | N43: ANO-001 | O43: Écart avec le cahier : il annonce 10 053 fermes évaluées (chiffre du relevé du 19/10) ; l'API en renvoie 38 468 aujourd'hui. Voir l'anomalie ouverte.
A44: GOU-06 | B44: Suivi | C44: Gouvernance et appuis | D44: /selection | E44: Agent ATDA | F44: P1 | G44: Sélection proposée (GOU-05). | H44: 1. Valider avec un motif et la case « J'ai contrôlé un échantillon… ». 2. Tenter de valider avec le compte qui a lancé la sélection. | I44: La validation ouvre la période de contestation de 15 jours. Le lanceur ne peut pas valider sa propre sélection. | J44: Le lanceur (responsable) ne peut pas valider sa propre sélection (403) ; validation sans motif refusée (400) ; l'agent valide avec motif : « validee », contestation ouverte jusqu'au None. | K44: OK | L44: Claude (essai automatisé) | M44: 46323 | O44: Vérifié par l'API ; la case « J'ai contrôlé un échantillon » est dans l'écran, non vue.
A45: GOU-07 | B45: Suivi | C45: Gouvernance et appuis | D45: /programmes | E45: Producteur | F45: P1 | G45: Programme ouvert et programme clos en base. | H45: 1. « Programmes » : candidater au programme ouvert (cocher la confirmation, « Déposer ma candidature »). 2. Ouvrir l'onglet « Clos ». | I45: Candidature déposée. Le programme clos affiche « Les candidatures sont closes. » sans bouton (l'API répond « Ce programme est clos depuis le JJ/MM/AAAA. »). | J45: Candidature déposée (201, statut deposee), 2e candidature refusée (409) ; programme clos : 400 « Ce programme est clos depuis le 31/12/2025. Les candidatures ne sont plus acceptées. ». | K45: OK | L45: Claude (essai automatisé) | M45: 46323 | O45: Vérifié par l'API ; texte « Les candidatures sont closes. » sans bouton non vu à l'écran.
A46: GOU-08 | B46: Suivi | C46: Gouvernance et appuis | D46: /contestations | E46: Responsable de programme + Producteur + Agent ATDA | F46: P2 | G46: Candidature en cours. | H46: 1. Responsable (0197000004) : refuser une candidature avec un motif. 2. Producteur : « Programmes », lire le motif et la date, « Contester la décision ». 3. Agent : ouvrir « Candidatures ». | I46: La contestation n'est possible qu'une fois, sous 15 jours. La candidature repasse en instruction ; l'agent la voit avec le badge « Contestée » et le motif. | J46: Refus sans motif refusé (reason_required) ; refus motivé ; contestation acceptée : la candidature repasse « en_instruction » ; une 2e contestation est refusée (invalid_status) ; l'agent voit la candidature avec le motif de contestation « Inscrit avant la date limite. ». | K46: OK | L46: Claude (essai automatisé) | M46: 46323 | O46: Vérifié par l'API ; badge « Contestée » non vu à l'écran ; délai de 15 jours non rejoué.
A47: GOU-09 | B47: Suivi | C47: Gouvernance et appuis | D47: /alertes | E47: Agent ATDA | F47: P2 | G47: Connecté (téléphone 0197000002). | H47: 1. « Envoyer une alerte » : catégorie ravageur, gravité avertissement, Alibori, filière maïs. 2. Envoyer puis ouvrir « Boîte d'envoi ». | I47: Un SMS par producteur concerné, avec nombre de segments et encodage, statut « livré » (bandeau Simulation). | J47: Alerte ravageur envoyée : {'sent': 9, 'delivered': 9, 'failed': 0} ; boîte d'envoi : 9 SMS dont la 1re ligne indique segments=2, encodage=UCS-2, statut=livre. | K47: OK | L47: Claude (essai automatisé) | M47: 46323 | O47: Vérifié par l'API ; bandeau « Simulation » non vu à l'écran.
A48: GOU-10 | B48: Suivi | C48: Gouvernance et appuis | D48: /alertes | E48: Agent ATDA + Administrateur MAEP | F48: P3 | G48: Connecté (téléphone 0197000002). | H48: 1. Créer une alerte de gravité « urgente ». | I48: L'alerte urgente exige une seconde validation avant diffusion. | J48: Alerte urgente créée au statut « en_attente_validation » ; envoi immédiat refusé (400 approval_required) : seconde validation exigée. | K48: OK | L48: Claude (essai automatisé) | M48: 46323 | O48: Vérifié par l'API ; la seconde validation par un autre compte n'a pas été jouée.
A49: GOU-11 | B49: Suivi | C49: Gouvernance et appuis | D49: /messages | E49: Producteur + Agent ATDA | F49: P2 | G49: Producteur rattaché à un agent de commune. | H49: 1. Producteur : « Mes messages », onglet « Mon agent ATDA », écrire et « Envoyer ». 2. Agent : « Mes messages », onglet « Messages des producteurs », répondre. | I49: L'agent reçoit le message et répond ; le producteur est prévenu aussi par SMS (visible dans la boîte d'envoi). | J49: Le producteur écrit à son agent (201), la conversation apparaît côté agent, l'agent répond (201), le producteur relit la réponse ; boîte d'envoi : SMS « votre agent ATDA vous a répondu. Ouvrez « Mes messages » » livré au producteur. | K49: OK | L49: Claude (essai automatisé) | M49: 46323 | O49: Vérifié par l'API.
A50: GOU-12 | B50: Suivi | C50: Gouvernance et appuis | D50: /formations | E50: Agent ATDA + Transformateur | F50: P3 | G50: Connecté (téléphone 0197000002). | H50: 1. Agent : « Formations », « Programmer une formation » (public : transformateurs, date du jour). 2. Transformateur du même département : « M'inscrire ». 3. Agent : « Inscrits et présence », cocher la présence, onglet « Rapport ». | I50: Inscription volontaire, présence enregistrée à partir du jour de la séance, rapport par département (inscrits, présents, taux). | J50: Formation « stockage » programmée pour producteurs et transformateurs (aujourd'hui, Mairie de Kandi) ; inscription volontaire d'un producteur (201) ; un transformateur d'un autre département ne la voit pas (404) ; présence cochée (200) ; rapport par département : 1 inscrit(s), 1 présent(s), taux 100 %. | K50: OK | L50: Claude (essai automatisé) | M50: 46323 | O50: Vérifié par l'API ; le test avec un transformateur du même département (Borgou) n'a pas été fait faute de séance dans ce département.
A51: SEA-01 | B51: Suivi | C51: Dashboard et suivi-évaluation | D51: /tableau-de-bord | E51: Administrateur MAEP | F51: P1 | G51: Connecté (téléphone 0197000005). | H51: 1. Ouvrir « Tableau de bord ». 2. Filtrer sur l'Alibori. | I51: Chaque chiffre affiche sa source et sa date ; les données POC sont marquées « données de démonstration » ; une valeur absente affiche « non disponible ». | J51: Tableau de bord national (administrateur) : chaque indicateur affiche sa valeur, son unité, sa source (« Registre Agri-Digit (prototype, données fictives) ») et sa date de mise à jour (ex. 48 producteurs inscrits, 42 validés). | K51: OK | L51: Claude (essai automatisé) | M51: 46323 | O51: Vérifié par l'API ; filtre Alibori et « non disponible » pour une valeur absente non contrôlés à l'écran.
A52: SEA-02 | B52: Suivi | C52: Dashboard et suivi-évaluation | D52: /suivi-evaluation | E52: Responsable de programme | F52: P1 | G52: Connecté (téléphone 0197000004). | H52: 1. Ouvrir « Suivi-évaluation ». 2. Lire « Production par filière et par saison », « Effectifs de producteurs validés », « Impact des appuis ». | I52: Cases de moins de 5 personnes « masquées » (l'administrateur les voit). Impact des appuis : « non disponible » avec 45 producteurs de démonstration, avec rappel que la comparaison n'est pas causale. | J52: Responsable de programme : « Production par filière et par saison » et « Effectifs de producteurs validés » affichent des cases masquées sous 5 personnes (masked=true, valeurs null, min_cell 5) ; l'administrateur voit les mêmes cases en clair (3 producteurs, 4 parcelles, 1 051 900 kg pour le maïs ; effectifs par département) ; « Impact des appuis » : available=false (« non disponible ») avec le rappel « Comparaison non causale : les appuis ne sont pas attribués au hasard… ». | K52: OK | L52: Claude (essai automatisé) | M52: 46323 | O52: Vérifié par l'API ; rendu des trois tableaux à l'écran non vu.
A53: SEA-03 | B53: Suivi | C53: Dashboard et suivi-évaluation | D53: /couverture | E53: Administrateur MAEP | F53: P2 | G53: Connecté (téléphone 0197000005). | H53: 1. Ouvrir « Couverture et importations ». 2. Saisir une statistique sans source. 3. Importer un lot JSON. | I53: Bandeau « Données de démonstration (non officielles) ». La veille signale le riz 2025 (couverture 52,9 %, importations +50 %, production −25 %) et le soja (63,4 %). Une saisie sans source est refusée. | J53: Page « Couverture et importations » : bandeau « Données de démonstration (non officielles) », veille avec riz (52,9 %) et soja (63,4 %) ; la saisie d'une statistique sans source est refusée par l'API (400 « source : Ce champ est obligatoire »). | K53: OK | L53: Claude (essai automatisé) | M53: 46323 | O53: Import d'un lot JSON non rejoué.
A54: SEA-04 | B54: Suivi | C54: Dashboard et suivi-évaluation | D54: /carte-acteurs | E54: Administrateur MAEP + Agent ATDA | F54: P2 | G54: Connecté (téléphone 0197000005). | H54: 1. Ouvrir « Carte des acteurs ». 2. Cocher/décocher les couches (sites, aménagements, organisations, coopératives). 3. Filtrer par filière. | I54: Coopératives et organisations sont placées au centre de leur département ; jamais de téléphone ni de nom. Les parcelles (avec code producteur) ne sont visibles que de l'agent et de l'administration. | J54: Carte des acteurs (administrateur) : 7 couches (sites 2, aménagements 1, organisations 1, coopératives 1, parcelles avec code producteur 47, entreprises 2, matériel 2) ; la page rappelle « jamais de téléphone ni de nom de personne » ; aucune fuite de nom ou de téléphone dans les données (SEC-05). | K54: OK | L54: Claude (essai automatisé) | M54: 46323 | O54: Les couches ont été listées, mais pas cochées/décochées ni filtrées par filière à l'écran.
A55: SEA-05 | B55: Suivi | C55: Dashboard et suivi-évaluation | D55: /exports | E55: Administrateur MAEP | F55: P3 | G55: Connecté (téléphone 0197000005). | H55: 1. Ouvrir « Exports ». 2. Exporter la liste des producteurs avec le motif « test de recette ». | I55: Fichier CSV téléchargé. Voir aussi SEC-02 pour le contrôle du motif et du journal. | J55: Export CSV des producteurs avec le motif « test de recette (export CSV) » : fichier CSV reçu (en-têtes code;npi;prenom;nom;…, 48 lignes). | K55: OK | L55: Claude (essai automatisé) | M55: 46323 | O55: Vérifié par l'API ; le téléchargement par le navigateur n'a pas été joué.
...

Sheet Anomalies
A1: Cahier de recette · Registre des anomalies
A2: Une ligne par anomalie. Reporter le N° (ANO-001…) dans la colonne « N° anomalie » du cas de test concerné. La ligne EXEMPLE montre le format attendu.
A4: N° | B4: Date | C4: Cas de test | D4: Module | E4: Titre | F4: Description et étapes pour reproduire | G4: Gravité | H4: Statut | I4: Rapporteur | J4: Assigné à | K4: Date de correction | L4: Commentaire / version corrigée
A5: EXEMPLE | B5: 29/10/2026 | C5: GOU-03 | D5: Gouvernance et appuis | E5: Le bouton « Payer » reste inactif après le 1er paiement | F5: 1. Producteur 0197000001, « Mes remboursements ». 2. Payer la 1re échéance (réussi). 3. Recharger : le bouton de la 2e échéance reste grisé. Attendu : bouton actif sur la prochaine échéance. | G5: Majeure | H5: Fermée | I5: A. Dossou | J5: Équipe dev | K5: 30/10/2026 | L5: Exemple fictif : ne pas compter.
A6: ANO-001 | B6: 46323 | C6: GOU-05 | D6: Gouvernance et appuis | E6: Nombre de fermes évaluées différent de celui du cahier (38 468 au lieu de 10 053) | F6: 1. Responsable de programme (0197000004), « Sélections », « Nouvelle sélection » : 2 000 bénéficiaires, poids 0,5 / 0,3 / 0,2, département Alibori. 2. Lancer. Obtenu : 2 000 retenus sur 38 468 fermes évaluées (API selection-runs, total_count). Attendu : 10 053 fermes évaluées, chiffre du cahier et de docs/demo/RELEVES_PARCOURS.md (relevé du 19/10). À trancher : mettre à jour la documentation et le cahier, ou corriger le jeu de fermes de démonstration. | G6: Mineure | H6: Ouverte | I6: Claude (essai automatisé)
A7: ANO-002 | B7: 46323 | C7: REG-01 | D7: Registre acteurs et actifs | E7: Fiche de démonstration du cas REG-01 déjà inscrite : l'étape 2 ne peut pas être rejouée | F7: 1. Déconnecté, « S'inscrire ». 2. NPI 1000000002, Awa SABI, téléphone 0197000099, consentement coché, valider. Obtenu : refus 409 « Ce producteur est déjà inscrit (NPI ou téléphone) » ; la fiche BJ-AGR-2026-000043 a été créée par les données de démonstration le 20/10 (journal d'audit). Attendu : fiche créée au statut « en attente ». Correction proposée : dans le cahier, utiliser le bouton « Démo » du formulaire (fiche neuve, NPI commençant par 8) ou réinitialiser les données avant la recette. | G7: Mineure | H7: Ouverte | I7: Claude (essai automatisé)
A8: ANO-003 | B8: 46323 | C8: SCO-03 | D8: Scoring crédit et aléas climatiques | E8: Cas SCO-03 : le facteur « Appuis remboursés » ne bouge pas quand on paie une échéance à venir | F8: 1. Agent financier : ouvrir un prêt à un producteur consentant. 2. Producteur : payer une échéance (FakePay réussi). 3. Revoir le score. Obtenu : facteur « Appuis remboursés » inchangé à 0,5 (score 79). Explication : le facteur ne compte que les échéances échues payées et reste neutre tant qu'aucune n'est échue (apps/credit/services.py). Attendu par le cahier : le facteur suit les échéances payées. Correction proposée : préciser le cas (échéance échue exigée) ou le rejouer avec une échéance échue. | G8: Cosmétique | H8: Ouverte | I8: Claude (essai automatisé)

Sheet Comptes de test
A1: Comptes de démonstration
A2: Source : docs/DEMO.md. Comptes fictifs, sans lien avec des personnes réelles.
A4: Rôle | B4: Téléphone | C4: Mot de passe | D4: Connexion | E4: Périmètre
A5: Producteur (Bio GOUNOU) | B5: 0197000001 | C5: code seul | D5: Code à 6 chiffres lu dans le bandeau « Simulation » | E5: Banikoara, Alibori
A6: Agent ATDA | B6: 0197000002 | C6: AgriDemo-2026! | D6: Code + mot de passe | E6: Alibori
A7: Agronome INRAB | B7: 0197000003 | C7: AgriDemo-2026! | D7: Code + mot de passe | E7: National
A8: Responsable de programme | B8: 0197000004 | C8: AgriDemo-2026! | D8: Code + mot de passe | E8: National
A9: Administrateur MAEP | B9: 0197000005 | C9: AgriDemo-2026! | D9: Code + mot de passe | E9: National
A10: Auditeur CoPil | B10: 0197000006 | C10: AgriDemo-2026! | D10: Code + mot de passe | E10: National
A11: Agent financier | B11: 0197000007 | C11: AgriDemo-2026! | D11: Code + mot de passe | E11: National
A12: Gestionnaire de coopérative | B12: 0197000008 | C12: AgriDemo-2026! | D12: Code + mot de passe | E12: Coopérative des producteurs de maïs de Banikoara
A13: Transformateur | B13: 0197000009 | C13: AgriDemo-2026! | D13: Code + mot de passe | E13: Parakou, Borgou
A14: Distributeur | B14: 0197000010 | C14: AgriDemo-2026! | D14: Code + mot de passe | E14: Cotonou, Littoral
A15: Représentant MTDI | B15: 0197000011 | C15: AgriDemo-2026! | D15: Code + mot de passe | E15: National
A16: Représentant MTDI n° 2 (second locuteur) | B16: 0197000012 | C16: AgriDemo-2026! | D16: Code + mot de passe | E16: National
A18: Données utiles pour les cas de test
A19: Application | B19: http://localhost:5173 (page de connexion : /connexion)
A20: API | B20: http://127.0.0.1:8000
A21: Lancement | B21: start.bat (Windows) ou ./start.sh ; « start.bat reset » remet les données de démonstration à zéro
A22: NPI d'inscription | B22: 1000000002 : Awa SABI, née le 1990-07-01 · 1000000004 : demande de consentement parental
A23: Téléphone libre | B23: 0197000099 (pour l'inscription d'un nouveau producteur)
A24: Paiement simulé | B24: Plafond 500 000 XOF · un numéro de payeur finissant par 0 échoue volontairement
A25: Code de connexion | B25: Affiché dans le bandeau « Simulation » de la page de connexion (jamais envoyé par SMS réel)
